Traceback (most recent call last):
  File "C:\Users\nabil\AppData\Local\Programs\Python\Python312\Lib\site-packages\jupyter_cache\executors\utils.py", line 58, in single_nb_execution
    executenb(
  File "C:\Users\nabil\AppData\Local\Programs\Python\Python312\Lib\site-packages\nbclient\client.py", line 1319, in execute
    return NotebookClient(nb=nb, resources=resources, km=km, **kwargs).execute()
           ^^^^^^^^^^^^^^^^^^^^^^^^^^^^^^^^^^^^^^^^^^^^^^^^^^^^^^^^^^^^^^^^^^^^^
  File "C:\Users\nabil\AppData\Roaming\Python\Python312\site-packages\jupyter_core\utils\__init__.py", line 165, in wrapped
    return loop.run_until_complete(inner)
           ^^^^^^^^^^^^^^^^^^^^^^^^^^^^^^
  File "C:\Users\nabil\AppData\Local\Programs\Python\Python312\Lib\asyncio\base_events.py", line 691, in run_until_complete
    return future.result()
           ^^^^^^^^^^^^^^^
  File "C:\Users\nabil\AppData\Local\Programs\Python\Python312\Lib\site-packages\nbclient\client.py", line 709, in async_execute
    await self.async_execute_cell(
  File "C:\Users\nabil\AppData\Local\Programs\Python\Python312\Lib\site-packages\nbclient\client.py", line 1062, in async_execute_cell
    await self._check_raise_for_error(cell, cell_index, exec_reply)
  File "C:\Users\nabil\AppData\Local\Programs\Python\Python312\Lib\site-packages\nbclient\client.py", line 918, in _check_raise_for_error
    raise CellExecutionError.from_cell_and_msg(cell, exec_reply_content)
nbclient.exceptions.CellExecutionError: An error occurred while executing the following cell:
------------------
import pandas as pd
from sqlalchemy import create_engine

# Mengimpor modul dengan alias untuk menghindari konflik
import pycaret.clustering as pyc
import pycaret.anomaly as pya

# --- Konfigurasi dan Muat Data (Tetap Sama) ---
db_user = 'postgres'
db_password = '123456789'  # Ganti dengan password Anda
db_host = 'localhost'
db_port = '5432'
db_name = 'iris_data'
table_name = 'iris_data'

try:
    db_uri = f'postgresql://{db_user}:{db_password}@{db_host}:{db_port}/{db_name}'
    engine = create_engine(db_uri)
    df = pd.read_sql_table(table_name, engine)
    print(f"Dataset berhasil dimuat dari tabel '{table_name}'.")
    display(df.head())
except Exception as e:
    print(f"Terjadi kesalahan: {e}")
------------------


[1;31m---------------------------------------------------------------------------[0m
[1;31mModuleNotFoundError[0m                       Traceback (most recent call last)
Cell [1;32mIn[2], line 5[0m
[0;32m      2[0m [38;5;28;01mfrom[39;00m [38;5;21;01msqlalchemy[39;00m [38;5;28;01mimport[39;00m create_engine
[0;32m      4[0m [38;5;66;03m# Mengimpor modul dengan alias untuk menghindari konflik[39;00m
[1;32m----> 5[0m [38;5;28;01mimport[39;00m [38;5;21;01mpycaret[39;00m[38;5;21;01m.[39;00m[38;5;21;01mclustering[39;00m [38;5;28;01mas[39;00m [38;5;21;01mpyc[39;00m
[0;32m      6[0m [38;5;28;01mimport[39;00m [38;5;21;01mpycaret[39;00m[38;5;21;01m.[39;00m[38;5;21;01manomaly[39;00m [38;5;28;01mas[39;00m [38;5;21;01mpya[39;00m
[0;32m      8[0m [38;5;66;03m# --- Konfigurasi dan Muat Data (Tetap Sama) ---[39;00m

[1;31mModuleNotFoundError[0m: No module named 'pycaret'

